<?xml version="1.0" encoding="utf-8"?>
<!-- This URDF was automatically created by SolidWorks to URDF Exporter! Originally created by Stephen Brawner (brawner@gmail.com)
     Commit Version: 1.5.1-0-g916b5db  Build Version: 1.5.7152.31018
     For more information, please see http://wiki.ros.org/sw_urdf_exporter -->
<robot
  name="scara">
  <link
    name="base_link">
    <inertial>
      <origin
        xyz="-0.00011095 0.011706 0.22021"
        rpy="0 0 0" />
      <mass
        value="11.63" />
      <inertia
        ixx="0.26065"
        ixy="-0.00010475"
        ixz="8.587E-05"
        iyy="0.22933"
        iyz="-0.010595"
        izz="0.063336" />
    </inertial>
    <visual>
      <origin
        xyz="0 0 0"
        rpy="0 0 0" />
      <geometry>
        <mesh
          filename="package://scara/meshes/base_link.STL" />
      </geometry>
      <material
        name="">
        <color
          rgba="0.79216 0.81961 0.93333 1" />
      </material>
    </visual>
    <collision>
      <origin
        xyz="0 0 0"
        rpy="0 0 0" />
      <geometry>
        <mesh
          filename="package://scara/meshes/base_link.STL" />
      </geometry>
    </collision>
  </link>
  <link
    name="Link1">
    <inertial>
      <origin
        xyz="0.14744 0.035552 -7.4228E-08"
        rpy="0 0 0" />
      <mass
        value="1.6797" />
      <inertia
        ixx="0.001999"
        ixy="0.00046658"
        ixz="2.0802E-08"
        iyy="0.019536"
        iyz="1.1689E-09"
        izz="0.018224" />
    </inertial>
    <visual>
      <origin
        xyz="0 0 0"
        rpy="0 0 0" />
      <geometry>
        <mesh
          filename="package://scara/meshes/Link1.STL" />
      </geometry>
      <material
        name="">
        <color
          rgba="0.79216 0.81961 0.93333 1" />
      </material>
    </visual>
    <collision>
      <origin
        xyz="0 0 0"
        rpy="0 0 0" />
      <geometry>
        <mesh
          filename="package://scara/meshes/Link1.STL" />
      </geometry>
    </collision>
  </link>
  <joint
    name="Joint1"
    type="revolute">
    <origin
      xyz="0 0.0625 0.191"
      rpy="1.5708 0 1.1826" />
    <parent
      link="base_link" />
    <child
      link="Link1" />
    <axis
      xyz="0 1 0" />
    <limit
      lower="-1.57"
      upper="2.5"
      effort="0"
      velocity="0" />
  </joint>
  <link
    name="Link2">
    <inertial>
      <origin
        xyz="0.11966 0.1221 7.2579E-06"
        rpy="0 0 0" />
      <mass
        value="7.5355" />
      <inertia
        ixx="0.031732"
        ixy="0.0058572"
        ixz="6.1421E-06"
        iyy="0.083983"
        iyz="-3.6771E-06"
        izz="0.10023" />
    </inertial>
    <visual>
      <origin
        xyz="0 0 0"
        rpy="0 0 0" />
      <geometry>
        <mesh
          filename="package://scara/meshes/Link2.STL" />
      </geometry>
      <material
        name="">
        <color
          rgba="0.79216 0.81961 0.93333 1" />
      </material>
    </visual>
    <collision>
      <origin
        xyz="0 0 0"
        rpy="0 0 0" />
      <geometry>
        <mesh
          filename="package://scara/meshes/Link2.STL" />
      </geometry>
    </collision>
  </link>
  <joint
    name="Joint2"
    type="continuous">
    <origin
      xyz="0.325 0.028998 0"
      rpy="0 0.73996 0" />
    <parent
      link="Link1" />
    <child
      link="Link2" />
    <axis
      xyz="0 1 0" />
    <limit
      lower="0"
      upper="0"
      effort="0"
      velocity="0" />
  </joint>
  <link
    name="Link3">
    <inertial>
      <origin
        xyz="-0.0001139 0.15798 3.8177E-05"
        rpy="0 0 0" />
      <mass
        value="0.083171" />
      <inertia
        ixx="0.0015219"
        ixy="-3.524E-08"
        ixz="-4.2008E-08"
        iyy="9.0892E-06"
        iyz="-2.8191E-08"
        izz="0.0015218" />
    </inertial>
    <visual>
      <origin
        xyz="0 0 0"
        rpy="0 0 0" />
      <geometry>
        <mesh
          filename="package://scara/meshes/Link3.STL" />
      </geometry>
      <material
        name="">
        <color
          rgba="0.79216 0.81961 0.93333 1" />
      </material>
    </visual>
    <collision>
      <origin
        xyz="0 0 0"
        rpy="0 0 0" />
      <geometry>
        <mesh
          filename="package://scara/meshes/Link3.STL" />
      </geometry>
    </collision>
  </link>
  <joint
    name="Joint3"
    type="prismatic">
    <origin
      xyz="0.275 0 0"
      rpy="3.1416 0.42498 3.1416" />
    <parent
      link="Link2" />
    <child
      link="Link3" />
    <axis
      xyz="0 1 0" />
    <limit
      lower="0"
      upper="-0.15"
      effort="0"
      velocity="0" />
  </joint>
</robot>
